Workbook

Sheet 1-Теория
B1: ЗАДАЧА ВЫБОРА ОПТИМАЛЬНОЙ ПРОДОЛЖИТЕЛЬНОСТИ РАБОЧЕГО ВРЕМЕНИ: М 1
C2: Обозначения компьютерной модели | D2: Таблица 1.1 | F2: Примеры расчетов рабочего времениTp=15 | J2: Таблица 1.2
B3: Обозначение | C3: Экономический смысл | D3: Примечание | F3: № п/п | G3: W
B4: tp, tc | C4: Среднедневная продолжительность рабочего и свободного времени соответственно (в рабочие дни) | D4: Сумма рабочего и свободного времени + Тн =24 часа | F4: 1 | G4: 0.2 | H4: =7.5+(1-1/G4)*7.5 -> -22.5 | I4: 8 | J4: 0 | K4: =15-J4 -> 15
B5: Tн | C5: Необходимые затраты времени (сон, питание, обязательства и др.) (в рабочие дни) | D5: Не менее 8 часов | F5: 2 | G5: 0.6 | H5: =7.5+(1-1/G5)*7.5 -> 2.5 | I5: 8 | J5: =MAX(H5,I5) -> 8 | K5: =15-J5 -> 7
B6: Tр | C6: Сумма рабочего и свободного (досугового) времени (в рабочие дни), час | D6: Не более 16 часов | F6: 3 | G6: 1 | H6: =7.5+(1-1/G6)*7.5 -> 7.5 | I6: 8 | J6: =MAX(H6,I6) -> 8 | K6: =15-J6 -> 7
B7: f(tp, tc) | C7: Функция полезности свободного и рабочего времени | D7: Общий случай | F7: 4 | G7: 1.5 | H7: =7.5+(1-1/G7)*7.5 -> 10 | I7: 8 | J7: =MAX(H7,I7) -> 10 | K7: =15-J7 -> 5
B8: W | C8: Полезность единицы рабочего времени, выраженное в единицах полезности свободного времени | D8: W > 0 | F8: 5 | G8: 2 | H8: =7.5+(1-1/G8)*7.5 -> 11.25 | I8: 8 | J8: =MAX(H8,I8) -> 11.25 | K8: =15-J8 -> 3.75
B9: w | C9: Индекс полезности единицы рабочего времени, который определяется денежной оплатой труда | D9: w>0 | F9: 6 | G9: 2.5 | H9: =7.5+(1-1/G9)*7.5 -> 12 | I9: 8 | J9: =MAX(H9,I9) -> 12 | K9: =15-J9 -> 3
B10: v | C10: Индекс полезности единицы рабочего времени, который определяется моральными стимулами | D10: Интерввал -0,8<v<0,8
B11: b | C11: Коэффициент синергии свободного и рабочего времени | D11: 0 < b < 1
B12: U(tp) | C12: Функция субъективной полезности рабочего времени в среднем за рабочий день | D12: Wс = 1, W = Wр /Wс
C13: Внешнее ограничение на продолжительность рабочего времени, определяемое рабочим местом | D13: Определяется трудовым контрактом
B21: Задача выбора рабочего времени

Sheet 3-Тест ДЛЯ ВАС
B1: ЗАДАЧА ВЫБОРА ОПТИМАЛЬНОЙ ПРОДОЛЖИТЕЛЬНОСТИ РАБОЧЕГО ВРЕМЕНИ: М 1
A2: Заполните следующие таблицы (3.1, 3.2, 3.3, 3.4) в выделенных цветом ячейках в столбце D, цвет =>
C3: Исходные данные для оценки предельной продолжительности рабочего времени | E3: Таблица 3.1
B4: № п/п | C4: Вопросы | D4: Ответы | E4: Оценка корректности введенного ответа
B5: 1 | C5: Сколько времени Вы спите в рабочие дни для поддержания нормальной трудоспособности | D5: 7 | E5: =IF(D5<6.5,"Введите значение большее, либо равное 6,5",IF(D5>12,"Введите значение меньшее, либо равное 12","Ответ принят")) -> Ответ принят
B6: 2 | C6: Продолжительность утреннего завтрака и процедур | D6: 0.5 | E6: =IF(D6<0.1,"Введите значение большее, либо равное 0,1",IF(D6>1,"Введите значение меньшее, либо равное 1","Ответ принят")) -> Ответ принят
B7: 3 | C7: Продолжительность поездок на работу и обратно (- работа при поездке) | D7: 0.5 | E7: =IF(D7<0.1,"Введите значение большее, либо равное 0,1",IF(D7>1,"Введите значение меньшее, либо равное 1","Ответ принят")) -> Ответ принят
B8: 4 | C8: Затраты времени на обеденный перерыв и «перекусы» в вечернее время | D8: 0.5 | E8: =IF(D8<0.1,"Введите значение большее, либо равное 0,1",IF(D8>0.5,"Введите значение меньшее, либо равное 0,5","Ответ принят")) -> Ответ принят
B9: 5 | C9: Дополнительные перерывы работы, включая звонки по телефону, беседы на темы не связанные с работой и др. | D9: 0.5 | E9: =IF(D9<0.1,"Введите значение большее, либо равное 0,1",IF(D9>0.5,"Введите значение меньшее, либо равное 0,5","Ответ принят")) -> Ответ принят
B10: 6 | C10: Минимальные в рабочие дни затраты времени на развлечение на сайтах интернета, социальных сетях и др. | D10: 0.2 | E10: =IF(D10<0.1,"Введите значение большее, либо равное 0,1",IF(D10>0.5,"Введите значение меньшее, либо равное 0,5","Ответ принят")) -> Ответ принят
B11: 7 | C11: Затраты в рабочие дни времени на Ваши суперувлечения, обяза-тельное посещение родных от которых нельзя отказаться и др. | D11: 0.2 | E11: =IF(D11<0,"Введите значение большее, либо равное 0",IF(D11>1,"Введите значение меньшее, либо равное 1","Ответ принят")) -> Ответ принят
B13: 8 | C13: Сумма обязательных затрат времени в среднем за рабочие дни | D13: =SUM(D5:D11) -> 9.4 | E13: Служебные расчеты
B14: 9 | C14: Tp - Суммарная продолжительность рабочего и свободного времени | D14: =24-D13 -> 14.6 | E14: Служебные расчеты
C16: Комментарий результата
C17: =IF(D14>16,"Вы подобны Наполеону, который спал не более 4 часов. Может измените свои ответы?",IF(D14>14,"Вы потенциальный трудоголик. Успехов!",IF(D14>12.5,"У Вас есть еще возможность повысить потенциал своей трудовой активности","У Вас значение потенциала трудовой активности меньше допустимого. Вы можете скорректировать данные или прекратить тестирование"))) -> Вы потенциальный трудоголик. Успехов!
B22: Исходные данные для оценки внешнего ограничения на выбор рабочего времени | E22: Таблица 3.2
B23: № п/п | C23: Вопросы | D23: Ответы | E23: Оценка корректности введенного ответа
B24: 1 | C24: Вы работаете (хотите, планируете работать) в условиях нормированного рабочего дня: Да – 1, Нет – 0 | D24: 1 | E24: =IF(D24=1,"Ответ принят",IF(D24=0,"Ответ принят","Введен некорректный ответ")) -> Ответ принят
B25: 2 | C25: Если Да. Ваша продолжительность основного рабочего дня | D25: 8 | E25: =IF(AND(D24=1,D25>=1,D25<=10),"Ответ принят",IF(D24=0,"Ответ не требуется","Введен некорректный ответ")) -> Ответ принят
B26: 3 | C26: Если Да. Средняя продолжительность работы по совмести-тельству, включая временные контракты, консультационные услуги, личное подсобное хозяйство в различных формах и др. | D26: 0.1 | E26: =IF(AND(D24=1,D26>=0,D26<=5),"Ответ принят",IF(D24=0,"Ответ не требуется","Введен некорректный ответ")) -> Ответ принят
B27: 4 | C27: Если Да.Суммарная продолжительность обязательных работ | D27: =IF(D24=1,IF((D25+D26+0.5)<D29,(D25+D26),"Не корректно"),0) -> 8.1 | E27: Сужебные расчеты
B29: 5 | C29: Предельные затраты рабочего и свободного времени в среднем. Требуется, чтобы обязательные работы + 0,5 часа не превышали это значение | D29: =D14 -> 14.6 | E29: Служебные расчеты
C31: Исходные данные для оценки полезности ЗП одного часа рабочего времени | E31: Таблица 3.3
B32: № п/п | C32: Вопросы | D32: Ответы | E32: Оценка корректности введенного ответа
B33: 1 | C33: Какая месячная сумма денежных средств Вам необходима как ресурс для исполнения Вами реальных обязательств, тыс. руб. | D33: 100 | E33: =IF(AND(D33>=0.5*$D$37,D33<=1.5*$D$37),"Ответ принят","Хороший ресурс!") -> Ответ принят
B34: 2 | C34: Какую сумму денежных средств в среднем Вы получаете как проценты с накоплений, тыс. руб. | D34: 0 | E34: =IF(AND(D34>=0*$D$37,D34<=2*$D$37),"Ответ принят","Введен некорректный ответ") -> Ответ принят
B35: 3 | C35: Среднемесячный доход от сдачи в аренду недвижимости, тыс. руб. | D35: 0 | E35: =IF(AND(D35>=0*$D$37,D35<=2*$D$37),"Ответ принят","Введен некорректный ответ") -> Ответ принят
B36: 4 | C36: Среднемесячная финансовая помощь родных, друзей и др., тыс. руб. | D36: 0 | E36: =IF(AND(D36>=0*$D$37,D36<=2*$D$37),"Ответ принят","Введен некорректный ответ") -> Ответ принят
B37: 5 | C37: Экспертная оценки средней ЗП на рынке труда для Вашей профессии, Zp . | D37: 100 | E37: Можете изменить
B38: 6 | C38: Требуемые месячные финансовые ресурсы (п.1 - пп. 2-4), тыс. руб. | D38: =D33-SUM(D34:D36) -> 100 | E38: =IF(AND(D38>=0.8*$D$37,D38<=2.5*$D$37),"Ответы приняты","Ответы требуют коректировки") -> Ответы приняты
B39: 4 | C39: Оценка полезности заработной платы единицы рабочего времени, w | D39: =D38/D37 -> 1 | E39: Служебные расчеты
B41: Исходные данные для оценки полезности моральных стимулов одного часа рабочего времени | E41: Таблица 3.4
B42: № п/п | C42: Вопросы | D42: Ответы | E42: Оценка корректности введенного ответа
B43: 1 | C43: Месячная сумма денежных средств по Вашей оценке эквивалентная стимулам работодателя (благо с +), тыс. руб. | D43: 8 | E43: =IF(AND(D43>=0,D43<=0.5*$D$37),"Ответ принят","Не корректный ответ!") -> Ответ принят
B44: 2 | C44: Месячная сумма денежных средств по Вашей оценке эквивалентна антистимулам работодателя (ущерб с -), тыс. руб. | D44: -0.5 | E44: =IF(AND(D44<=0,D44>=-$D$37),"Ответ принят","Введен некорректный ответ") -> Ответ принят
B45: 3 | C45: Среднемесячная личная оценка (+ или -) выбора Вашей профессии, специализации в сравнении с базой заработной платы, тыс. руб. | D45: 4 | E45: =IF(AND(D45>=-0.5*$D$37,D45<=0.5*$D$37),"Ответ принят","Введен некорректный ответ") -> Ответ принят
B46: 4 | C46: Сравнительная среднемесячная личная оценка (+ или -) условий реализации Вашей профессии, специализации, тыс. руб. | D46: 0 | E46: =IF(AND(D46>=-0.5*$D$37,D46<=0.5*$D$37),"Ответ принят","Введен некорректный ответ") -> Ответ принят
B47: 5 | C47: Значение экспертной оценки Zp | D47: =D37 -> 100 | E47: Служебные действия
B48: 6 | C48: Сумма нематериальных благ в месяц , тыс. руб. (сумма пп. 1-4) | D48: =D43+SUM(D44:D46) -> 11.5 | E48: =IF(AND(D48>=-0.8*$D$37,D48<=0.8*$D$37),"Ответы приняты","Ответы требуют коректировки") -> Ответы приняты
B49: 4 | C49: Индекс оценка полезности нематериальных благ рабочего времени, v | D49: =D48/D47 -> 0.115 | E49: Служебные расчеты
...

Sheet 4-Анализ решения
B1: ЗАДАЧА ВЫБОРА ОПТИМАЛЬНОЙ ПРОДОЛЖИТЕЛЬНОСТИ РАБОЧЕГО ВРЕМЕНИ: М 1
H2: Вопросы к тестируемому
B3: Оптимальное решение, параметры задачи оптимизации, анализ и оценки результатов | E3: Таблица 4.1 | H3: Ответы ДА или НЕТ
B4: Обозначение | C4: Наименование параметра | D4: Значение | E4: Анализ и оценки
B5: Tн | C5: ='3-Тест ДЛЯ ВАС'!C13 -> Сумма обязательных затрат времени в среднем за рабочие дни | D5: ='3-Тест ДЛЯ ВАС'!D13 -> 9.4 | E5: =IF(D5<10,"У Вас хороший потенциал трудовой активности","Может больше работать и больше отдыхать?") -> У Вас хороший потенциал трудовой активности | G5: Вы работаете? | I5: ДА
B6: Tр | C6: ='3-Тест ДЛЯ ВАС'!C14 -> Tp - Суммарная продолжительность рабочего и свободного времени | D6: ='3-Тест ДЛЯ ВАС'!D14 -> 14.6 | E6: =IF(D6<14,"У Вас низкий потенциал трудовой активности","Может меньше работать и больше отдыхать?") -> Может меньше работать и больше отдыхать? | G6: Если нет, хотите работать?
B7: W | C7: Оценка полезности часа рабочего времени, выраженное в единицах свободного времени | D7: ='3-Тест ДЛЯ ВАС'!D50 -> 1.115 | E7: =IF(D7<1,"Вы цените сводное время выше рабочего. Успехов в Ваших увлечениях","Успешного Вам карьерного роста") -> Успешного Вам карьерного роста | G7: Если работаете, хотите сменить работу? | I7: НЕТ
C8: Оценка минимальной полезности часа рабочего времени, для мотивации к работе | D8: =0.5 -> 0.5 | E8: =IF(D7>0.5,IF(D7<0.1,"Вы еще цените работу как многие работники", "У Вас высокая мотивация к труду"),"Что то не нормально в Вашем государстве!") -> У Вас высокая мотивация к труду | G8: Вам хочется работать больше? | I8: НЕТ
B9: b | C9: Значение коэффициента синергии полезностей свободного и рабочего времени | D9: =1/D6 -> 0.068493151 | E9: =IF(D9>0.125,"Рекомендуем Вам изменить данные таблицы 2.1","У Вас хороший потенциаал для карьерного роста и хорошего отдыха") -> У Вас хороший потенциаал для карьерного роста и хорошего отдыха | G9: Вам хочется больше отдыхать? | I9: ДА
C10: Ограничение на продолжительность рабочего времени, определяемое трудовым контрактом | D10: ='3-Тест ДЛЯ ВАС'!D27 -> 8.1 | E10: =IF($D$10<$D$11,"Рекомендуем Вам изменить данные таблицы 3.2","Ваш трудовой потенциал ограничен внешними условиями") -> Ваш трудовой потенциал ограничен внешними условиями
C11: Стационарная точка функции полезности рабочего времени | D11: =(1-1/(2*D7))*D6 -> 8.0529148 | E11: =IF(AND($D$11>$D$10,D7>D8), "Вы свободны в выборе нужного Вам решения","Вы не свободны в выборе рабочего времени. Выберите решение по вариантам 1 или 2") -> Вы не свободны в выборе рабочего времени. Выберите решение по вариантам 1 или 2 | G11: Вы согласны с оценками для ВАС? | I11: ДА
C12: Оптимальная продолжительность рабочего времени, формула по варианту 1. Выполняю условие трудового контракта. | D12: =IF(D7>D8,MAX(D10,D11),D10) -> 8.1 | E12: =IF(D12>8,IF(D12>(D5-4),"Вы цените работу , наверное, для Вас она многое значит", "Поздравляю, работа для Вас - лучший отдых!"),"Рекомендуем Вам разобраться в ценностях жизни") -> Вы цените работу , наверное, для Вас она многое значит | I12: СПАСИБО ЗА ОТВЕТЫ
C13: Значение субъективной полезности рабочего и свободного времени | D13: =-D9*D7*D12*D12+(D7-1+D6*D9*D7)*D12+D6 -> 19.552373 | E13: =IF(D13>20,"Полезность Вашего выбора работы и отдыха выше среднего уровня","Есть возможность повысить пользу от работы и отдыха") -> Есть возможность повысить пользу от работы и отдыха | F13: =-1/16*8*8+8+16 -> 20
F15: Вариант 2: Решение задачи выбора рабочего времени
C21: Задача выбора рабочего времени Вариант 1: Решение задачи выбора рабочего времени
